<?xml version="1.0" ?>
<!-- =================================================================================== -->
<!-- |    This document was autogenerated by xacro from swerve_steer.xacro             | -->
<!-- |    EDITING THIS FILE BY HAND IS NOT RECOMMENDED                                 | -->
<!-- =================================================================================== -->
<robot name="swerve-steer" xmlns:xacro="http://www.ros.org/wiki/xacro">
  <!-- *************************** XACRO MACROS *************************** -->
  <!-- Parent Frame = a frame fixed to the base, centered on the axis of rotation for this flipper's steering DOF -->
  <!-- ************************* ROBOT DEFINITION ************************* -->
  <link name="world"/>
  <joint name="world_base" type="floating">
    <origin rpy="0 0 0" xyz="0 0 0"/>
    <parent link="world"/>
    <child link="dummy"/>
  </joint>
  <!-- just for visualization: base post -->
  <link name="dummy"/>
  <joint name="dummy_to_base" type="fixed">
    <origin rpy="0 0 0" xyz="0 0 0"/>
    <parent link="dummy"/>
    <child link="base_link"/>
  </joint>
  <link name="map"/>
  <joint name="world_map" type="fixed">
    <origin rpy="0 0 0" xyz="0 0 0"/>
    <parent link="world"/>
    <child link="map"/>
  </joint>
  <link name="base_link">
    <visual>
      <origin rpy="0 0 0" xyz="0 0 0"/>
      <geometry>
        <mesh filename="package://swerve_steer_description/meshes/Main_Box_Visual.stl"/>
      </geometry>
      <material name="burnt_orange">
        <color rgba="0.8 0.33 0.0 1"/>
      </material>
    </visual>
    <collision>
      <origin rpy="0 0 0" xyz="0 0 0"/>
      <geometry>
        <mesh filename="package://swerve_steer_description/meshes/Main_Box_Collision.stl"/>
      </geometry>
    </collision>
    <inertial>
      <origin rpy="0 0 0" xyz="0 0 0"/>
      <mass value="50"/>
      <inertia ixx="0.01" ixy="0.01" ixz="0.1" iyy="0.02" iyz="0.1" izz="0.02"/>
    </inertial>
  </link>
  <!--~~~~~~~~~~~~~~~~~~~ STEERING JOINT ~~~~~~~~~~~~~~~~~~~~~~~~~~~~~~~~~~~~~~~~-->
  <link name="module_1/steer">
    <visual>
      <origin rpy="0 0 0" xyz="0 0 0"/>
      <geometry>
        <mesh filename="package://swerve_steer_description/meshes/Steer.stl"/>
      </geometry>
      <material name="black">
        <color rgba="0 0 0 1"/>
      </material>
    </visual>
    <collision>
      <origin rpy="0 0 0" xyz="0 0 0"/>
      <geometry>
        <mesh filename="package://swerve_steer_description/meshes/Steer.stl"/>
      </geometry>
    </collision>
    <inertial>
      <origin rpy="0 0 0" xyz="0 0 0"/>
      <mass value="3.92"/>
      <inertia ixx="0.01" ixy="0.01" ixz="0.1" iyy="0.02" iyz="0.1" izz="0.02"/>
    </inertial>
  </link>
  <joint name="module_1/steering" type="continuous">
    <parent link="base_link"/>
    <child link="module_1/steer"/>
    <origin rpy="0 0 0" xyz="0.2159 0.2159 0"/>
    <axis xyz="0 0 1"/>
    <limit effort="104" velocity="0.8"/>
    <joint_properties damping="0.0" friction="0.0"/>
  </joint>
  <!--~~~~~~~~~~~~~~~~~~~~~~ WHEEL JOINT ~~~~~~~~~~~~~~~~~~~~~~~~~~~~~~~~~~~~~~~~-->
  <link name="module_1/wheel">
    <visual>
      <origin rpy="0 0 0" xyz="0 0 0"/>
      <geometry>
        <mesh filename="package://swerve_steer_description/meshes/Wheel_Visual.stl"/>
      </geometry>
      <material name="white">
        <color rgba="1 1 1 1"/>
      </material>
    </visual>
    <collision>
      <origin rpy="0 0 0" xyz="0 0 0"/>
      <geometry>
        <mesh filename="package://swerve_steer_description/meshes/Wheel_Collision.stl"/>
      </geometry>
    </collision>
    <inertial>
      <origin rpy="0 0 0" xyz="0 0 0"/>
      <mass value="1.6"/>
      <inertia ixx="0.01" ixy="0.01" ixz="0.1" iyy="0.02" iyz="0.1" izz="0.02"/>
    </inertial>
  </link>
  <joint name="module_1/drive" type="continuous">
    <parent link="module_1/steer"/>
    <child link="module_1/wheel"/>
    <origin rpy="0 0 0" xyz="0 0 0"/>
    <axis xyz="0 1 0"/>
    <limit effort="19" velocity="3.14"/>
    <joint_properties damping="0.0" friction="0.5"/>
  </joint>
  <!--~~~~~~~~~~~~~~~~~~~ STEERING JOINT ~~~~~~~~~~~~~~~~~~~~~~~~~~~~~~~~~~~~~~~~-->
  <link name="module_2/steer">
    <visual>
      <origin rpy="0 0 0" xyz="0 0 0"/>
      <geometry>
        <mesh filename="package://swerve_steer_description/meshes/Steer.stl"/>
      </geometry>
      <material name="black">
        <color rgba="0 0 0 1"/>
      </material>
    </visual>
    <collision>
      <origin rpy="0 0 0" xyz="0 0 0"/>
      <geometry>
        <mesh filename="package://swerve_steer_description/meshes/Steer.stl"/>
      </geometry>
    </collision>
    <inertial>
      <origin rpy="0 0 0" xyz="0 0 0"/>
      <mass value="3.92"/>
      <inertia ixx="0.01" ixy="0.01" ixz="0.1" iyy="0.02" iyz="0.1" izz="0.02"/>
    </inertial>
  </link>
  <joint name="module_2/steering" type="continuous">
    <parent link="base_link"/>
    <child link="module_2/steer"/>
    <origin rpy="0 0 0" xyz="-0.2159 0.2159 0"/>
    <axis xyz="0 0 1"/>
    <limit effort="104" velocity="0.8"/>
    <joint_properties damping="0.0" friction="0.0"/>
  </joint>
  <!--~~~~~~~~~~~~~~~~~~~~~~ WHEEL JOINT ~~~~~~~~~~~~~~~~~~~~~~~~~~~~~~~~~~~~~~~~-->
  <link name="module_2/wheel">
    <visual>
      <origin rpy="0 0 0" xyz="0 0 0"/>
      <geometry>
        <mesh filename="package://swerve_steer_description/meshes/Wheel_Visual.stl"/>
      </geometry>
      <material name="white">
        <color rgba="1 1 1 1"/>
      </material>
    </visual>
    <collision>
      <origin rpy="0 0 0" xyz="0 0 0"/>
      <geometry>
        <mesh filename="package://swerve_steer_description/meshes/Wheel_Collision.stl"/>
      </geometry>
    </collision>
    <inertial>
      <origin rpy="0 0 0" xyz="0 0 0"/>
      <mass value="1.6"/>
      <inertia ixx="0.01" ixy="0.01" ixz="0.1" iyy="0.02" iyz="0.1" izz="0.02"/>
    </inertial>
  </link>
  <joint name="module_2/drive" type="continuous">
    <parent link="module_2/steer"/>
    <child link="module_2/wheel"/>
    <origin rpy="0 0 0" xyz="0 0 0"/>
    <axis xyz="0 1 0"/>
    <limit effort="19" velocity="3.14"/>
    <joint_properties damping="0.0" friction="0.5"/>
  </joint>
  <!--~~~~~~~~~~~~~~~~~~~ STEERING JOINT ~~~~~~~~~~~~~~~~~~~~~~~~~~~~~~~~~~~~~~~~-->
  <link name="module_3/steer">
    <visual>
      <origin rpy="0 0 0" xyz="0 0 0"/>
      <geometry>
        <mesh filename="package://swerve_steer_description/meshes/Steer.stl"/>
      </geometry>
      <material name="black">
        <color rgba="0 0 0 1"/>
      </material>
    </visual>
    <collision>
      <origin rpy="0 0 0" xyz="0 0 0"/>
      <geometry>
        <mesh filename="package://swerve_steer_description/meshes/Steer.stl"/>
      </geometry>
    </collision>
    <inertial>
      <origin rpy="0 0 0" xyz="0 0 0"/>
      <mass value="3.92"/>
      <inertia ixx="0.01" ixy="0.01" ixz="0.1" iyy="0.02" iyz="0.1" izz="0.02"/>
    </inertial>
  </link>
  <joint name="module_3/steering" type="continuous">
    <parent link="base_link"/>
    <child link="module_3/steer"/>
    <origin rpy="0 0 0" xyz="-0.2159 -0.2159 0"/>
    <axis xyz="0 0 1"/>
    <limit effort="104" velocity="0.8"/>
    <joint_properties damping="0.0" friction="0.0"/>
  </joint>
  <!--~~~~~~~~~~~~~~~~~~~~~~ WHEEL JOINT ~~~~~~~~~~~~~~~~~~~~~~~~~~~~~~~~~~~~~~~~-->
  <link name="module_3/wheel">
    <visual>
      <origin rpy="0 0 0" xyz="0 0 0"/>
      <geometry>
        <mesh filename="package://swerve_steer_description/meshes/Wheel_Visual.stl"/>
      </geometry>
      <material name="white">
        <color rgba="1 1 1 1"/>
      </material>
    </visual>
    <collision>
      <origin rpy="0 0 0" xyz="0 0 0"/>
      <geometry>
        <mesh filename="package://swerve_steer_description/meshes/Wheel_Collision.stl"/>
      </geometry>
    </collision>
    <inertial>
      <origin rpy="0 0 0" xyz="0 0 0"/>
      <mass value="1.6"/>
      <inertia ixx="0.01" ixy="0.01" ixz="0.1" iyy="0.02" iyz="0.1" izz="0.02"/>
    </inertial>
  </link>
  <joint name="module_3/drive" type="continuous">
    <parent link="module_3/steer"/>
    <child link="module_3/wheel"/>
    <origin rpy="0 0 0" xyz="0 0 0"/>
    <axis xyz="0 1 0"/>
    <limit effort="19" velocity="3.14"/>
    <joint_properties damping="0.0" friction="0.5"/>
  </joint>
  <!--~~~~~~~~~~~~~~~~~~~ STEERING JOINT ~~~~~~~~~~~~~~~~~~~~~~~~~~~~~~~~~~~~~~~~-->
  <link name="module_4/steer">
    <visual>
      <origin rpy="0 0 0" xyz="0 0 0"/>
      <geometry>
        <mesh filename="package://swerve_steer_description/meshes/Steer.stl"/>
      </geometry>
      <material name="black">
        <color rgba="0 0 0 1"/>
      </material>
    </visual>
    <collision>
      <origin rpy="0 0 0" xyz="0 0 0"/>
      <geometry>
        <mesh filename="package://swerve_steer_description/meshes/Steer.stl"/>
      </geometry>
    </collision>
    <inertial>
      <origin rpy="0 0 0" xyz="0 0 0"/>
      <mass value="3.92"/>
      <inertia ixx="0.01" ixy="0.01" ixz="0.1" iyy="0.02" iyz="0.1" izz="0.02"/>
    </inertial>
  </link>
  <joint name="module_4/steering" type="continuous">
    <parent link="base_link"/>
    <child link="module_4/steer"/>
    <origin rpy="0 0 0" xyz="0.2159 -0.2159 0"/>
    <axis xyz="0 0 1"/>
    <limit effort="104" velocity="0.8"/>
    <joint_properties damping="0.0" friction="0.0"/>
  </joint>
  <!--~~~~~~~~~~~~~~~~~~~~~~ WHEEL JOINT ~~~~~~~~~~~~~~~~~~~~~~~~~~~~~~~~~~~~~~~~-->
  <link name="module_4/wheel">
    <visual>
      <origin rpy="0 0 0" xyz="0 0 0"/>
      <geometry>
        <mesh filename="package://swerve_steer_description/meshes/Wheel_Visual.stl"/>
      </geometry>
      <material name="white">
        <color rgba="1 1 1 1"/>
      </material>
    </visual>
    <collision>
      <origin rpy="0 0 0" xyz="0 0 0"/>
      <geometry>
        <mesh filename="package://swerve_steer_description/meshes/Wheel_Collision.stl"/>
      </geometry>
    </collision>
    <inertial>
      <origin rpy="0 0 0" xyz="0 0 0"/>
      <mass value="1.6"/>
      <inertia ixx="0.01" ixy="0.01" ixz="0.1" iyy="0.02" iyz="0.1" izz="0.02"/>
    </inertial>
  </link>
  <joint name="module_4/drive" type="continuous">
    <parent link="module_4/steer"/>
    <child link="module_4/wheel"/>
    <origin rpy="0 0 0" xyz="0 0 0"/>
    <axis xyz="0 1 0"/>
    <limit effort="19" velocity="3.14"/>
    <joint_properties damping="0.0" friction="0.5"/>
  </joint>
</robot>
